Workbook

Sheet Cover
A1: Capitol Booking System — Requirements Traceability Matrix
A3: Project | B3: Capitol Booking System (CBS), Vector Four — SS231 G03
A4: Source of truth | B4: Software Requirements Specification v1.1 (10-6-2026)
A5: Test basis | B5: docs/qa/manual-test-suite.md on branch test/manual-test-suite
A6: Code baseline | B6: main @ 010694c
A7: System under test | B7: https://capitolrestaurant.up.railway.app
A9: Sheets
A10: Summary | B10: Execution progress, pass rate and requirement coverage. All figures are formulas; do not edit.
A11: RTM | B11: One row per SRS requirement → linked test cases, findings and a computed verdict (forward and backward traceability).
A12: Test Cases | B12: All test cases with steps and expected results, plus the execution columns you fill in.
A13: Findings | B13: SRS-vs-app deviations found during test design (F-01 to F-31), with a defect workflow.
A14: Requirement IDs | B14: SRS IDs are used as written (REQ-*). The SRS does not number its business rules, flows, user classes or non-functional items, so the RTM assigns IDs (BR-01, SEQ-RES, NFR-SEC-01 …) with the SRS section next to each. BRIEF marks cases that come from the test brief rather than the SRS.
A16: How to record a run
A17: Cells to edit | B17: Only the yellow cells: Test Cases → Status, Actual Result, Defect / Finding ID, Tester, Date Executed, Build / Commit, Remarks, Verification Method; Findings → Status, Owner, Target Date, Resolution Notes. Everything else is reference data or a formula.
A18: Status values | B18: Not Run · Pass · Fail · Blocked · N/A (drop-down). A case that confirms a known finding is a Fail; put the F-xx in Defect / Finding ID.
A19: Outlook column | B19: 'Known deviation' means code review already predicts a Fail (the case references a finding). 'Expected to pass' means no known issue.
A20: Verification method | B20: Test = executed against the live site · Automated test = repo script · Inspection = result is certain from the code deployed on the live site (checked in its JS bundle) and the source at 010694c; used only for missing features and fixed validation rules. Re-confirm inspection results during the manual run and switch the method to Test.
A21: 30-min subset | B21: Test Cases → 30-min = Y marks the time-boxed run (about 28 minutes). Filter on it.
A22: Requirement verdict | B22: RTM → Verdict is computed: No coverage · Not run · In progress · Fail (any linked case failed) · Pass (all linked cases passed or N/A).
A24: Example of a filled row | B24: ID FR-02 · Status Fail · Actual Result: 'Guests = 9 accepted, calendar opened' · Defect / Finding ID F-03 · Tester M. Balidio · Date Executed 2026-10-08 · Build / Commit 010694c · Remarks: 'Matches known finding; SRS BR Party Size requires 10–50'

Sheet Summary
A1: Test Execution Summary
A3: Suite | B3: Total | C3: Pass | D3: Fail | E3: Blocked | F3: N/A | G3: Not Run | H3: Executed % | I3: Pass rate
A4: Smoke | B4: =COUNTIF('Test Cases'!$B$2:$B$155,A4) | C4: =COUNTIFS('Test Cases'!$B$2:$B$155,$A4,'Test Cases'!$N$2:$N$155,"Pass") | D4: =COUNTIFS('Test Cases'!$B$2:$B$155,$A4,'Test Cases'!$N$2:$N$155,"Fail") | E4: =COUNTIFS('Test Cases'!$B$2:$B$155,$A4,'Test Cases'!$N$2:$N$155,"Blocked") | F4: =COUNTIFS('Test Cases'!$B$2:$B$155,$A4,'Test Cases'!$N$2:$N$155,"N/A") | G4: =COUNTIFS('Test Cases'!$B$2:$B$155,$A4,'Test Cases'!$N$2:$N$155,"Not Run") | H4: =IF(B4=0,0,(B4-G4)/B4) | I4: =IF(C4+D4=0,0,C4/(C4+D4))
A5: Feature | B5: =COUNTIF('Test Cases'!$B$2:$B$155,A5) | C5: =COUNTIFS('Test Cases'!$B$2:$B$155,$A5,'Test Cases'!$N$2:$N$155,"Pass") | D5: =COUNTIFS('Test Cases'!$B$2:$B$155,$A5,'Test Cases'!$N$2:$N$155,"Fail") | E5: =COUNTIFS('Test Cases'!$B$2:$B$155,$A5,'Test Cases'!$N$2:$N$155,"Blocked") | F5: =COUNTIFS('Test Cases'!$B$2:$B$155,$A5,'Test Cases'!$N$2:$N$155,"N/A") | G5: =COUNTIFS('Test Cases'!$B$2:$B$155,$A5,'Test Cases'!$N$2:$N$155,"Not Run") | H5: =IF(B5=0,0,(B5-G5)/B5) | I5: =IF(C5+D5=0,0,C5/(C5+D5))
A6: Non-functional | B6: =COUNTIF('Test Cases'!$B$2:$B$155,A6) | C6: =COUNTIFS('Test Cases'!$B$2:$B$155,$A6,'Test Cases'!$N$2:$N$155,"Pass") | D6: =COUNTIFS('Test Cases'!$B$2:$B$155,$A6,'Test Cases'!$N$2:$N$155,"Fail") | E6: =COUNTIFS('Test Cases'!$B$2:$B$155,$A6,'Test Cases'!$N$2:$N$155,"Blocked") | F6: =COUNTIFS('Test Cases'!$B$2:$B$155,$A6,'Test Cases'!$N$2:$N$155,"N/A") | G6: =COUNTIFS('Test Cases'!$B$2:$B$155,$A6,'Test Cases'!$N$2:$N$155,"Not Run") | H6: =IF(B6=0,0,(B6-G6)/B6) | I6: =IF(C6+D6=0,0,C6/(C6+D6))
A7: Role matrix | B7: =COUNTIF('Test Cases'!$B$2:$B$155,A7) | C7: =COUNTIFS('Test Cases'!$B$2:$B$155,$A7,'Test Cases'!$N$2:$N$155,"Pass") | D7: =COUNTIFS('Test Cases'!$B$2:$B$155,$A7,'Test Cases'!$N$2:$N$155,"Fail") | E7: =COUNTIFS('Test Cases'!$B$2:$B$155,$A7,'Test Cases'!$N$2:$N$155,"Blocked") | F7: =COUNTIFS('Test Cases'!$B$2:$B$155,$A7,'Test Cases'!$N$2:$N$155,"N/A") | G7: =COUNTIFS('Test Cases'!$B$2:$B$155,$A7,'Test Cases'!$N$2:$N$155,"Not Run") | H7: =IF(B7=0,0,(B7-G7)/B7) | I7: =IF(C7+D7=0,0,C7/(C7+D7))
A8: DB / Security | B8: =COUNTIF('Test Cases'!$B$2:$B$155,A8) | C8: =COUNTIFS('Test Cases'!$B$2:$B$155,$A8,'Test Cases'!$N$2:$N$155,"Pass") | D8: =COUNTIFS('Test Cases'!$B$2:$B$155,$A8,'Test Cases'!$N$2:$N$155,"Fail") | E8: =COUNTIFS('Test Cases'!$B$2:$B$155,$A8,'Test Cases'!$N$2:$N$155,"Blocked") | F8: =COUNTIFS('Test Cases'!$B$2:$B$155,$A8,'Test Cases'!$N$2:$N$155,"N/A") | G8: =COUNTIFS('Test Cases'!$B$2:$B$155,$A8,'Test Cases'!$N$2:$N$155,"Not Run") | H8: =IF(B8=0,0,(B8-G8)/B8) | I8: =IF(C8+D8=0,0,C8/(C8+D8))
A9: Total | B9: =SUM(B4:B8) | C9: =SUM(C4:C8) | D9: =SUM(D4:D8) | E9: =SUM(E4:E8) | F9: =SUM(F4:F8) | G9: =SUM(G4:G8) | H9: =IF(B9=0,0,(B9-G9)/B9) | I9: =IF(C9+D9=0,0,C9/(C9+D9))
A11: By priority
A12: Priority | B12: Total | C12: Pass | D12: Fail | E12: Blocked | F12: N/A | G12: Not Run
A13: P1 | B13: =COUNTIF('Test Cases'!$H$2:$H$155,A13) | C13: =COUNTIFS('Test Cases'!$H$2:$H$155,$A13,'Test Cases'!$N$2:$N$155,"Pass") | D13: =COUNTIFS('Test Cases'!$H$2:$H$155,$A13,'Test Cases'!$N$2:$N$155,"Fail") | E13: =COUNTIFS('Test Cases'!$H$2:$H$155,$A13,'Test Cases'!$N$2:$N$155,"Blocked") | F13: =COUNTIFS('Test Cases'!$H$2:$H$155,$A13,'Test Cases'!$N$2:$N$155,"N/A") | G13: =COUNTIFS('Test Cases'!$H$2:$H$155,$A13,'Test Cases'!$N$2:$N$155,"Not Run")
A14: P2 | B14: =COUNTIF('Test Cases'!$H$2:$H$155,A14) | C14: =COUNTIFS('Test Cases'!$H$2:$H$155,$A14,'Test Cases'!$N$2:$N$155,"Pass") | D14: =COUNTIFS('Test Cases'!$H$2:$H$155,$A14,'Test Cases'!$N$2:$N$155,"Fail") | E14: =COUNTIFS('Test Cases'!$H$2:$H$155,$A14,'Test Cases'!$N$2:$N$155,"Blocked") | F14: =COUNTIFS('Test Cases'!$H$2:$H$155,$A14,'Test Cases'!$N$2:$N$155,"N/A") | G14: =COUNTIFS('Test Cases'!$H$2:$H$155,$A14,'Test Cases'!$N$2:$N$155,"Not Run")
A16: 30-minute subset
A17: Cases in subset | B17: =COUNTIF('Test Cases'!$M$2:$M$155,"Y")
A18: Executed | B18: =COUNTIFS('Test Cases'!$M$2:$M$155,"Y",'Test Cases'!$N$2:$N$155,"<>Not Run")
A19: Failed | B19: =COUNTIFS('Test Cases'!$M$2:$M$155,"Y",'Test Cases'!$N$2:$N$155,"Fail")
A21: Requirement coverage
A22: Requirements traced | B22: =COUNTA(RTM!$A$2:$A$41)
A23: With ≥ 1 test case | B23: =COUNTIF(RTM!$H$2:$H$41,">0")
A24: Coverage % | B24: =IF(B22=0,0,B23/B22)
A25: Verdict: Pass | B25: =COUNTIF(RTM!$O$2:$O$41,"Pass")
A26: Verdict: Fail | B26: =COUNTIF(RTM!$O$2:$O$41,"Fail")
A27: Verdict: In progress | B27: =COUNTIF(RTM!$O$2:$O$41,"In progress")
A28: Verdict: Not run | B28: =COUNTIF(RTM!$O$2:$O$41,"Not run")
A29: Verdict: No coverage | B29: =COUNTIF(RTM!$O$2:$O$41,"No coverage")
A31: Findings
A32: Status | B32: P1 | C32: P2 | D32: Total
A33: Open | B33: =COUNTIFS(Findings!$I$2:$I$33,A33,Findings!$B$2:$B$33,"P1*") | C33: =COUNTIFS(Findings!$I$2:$I$33,A33,Findings!$B$2:$B$33,"P2*") | D33: =B33+C33
A34: In progress | B34: =COUNTIFS(Findings!$I$2:$I$33,A34,Findings!$B$2:$B$33,"P1*") | C34: =COUNTIFS(Findings!$I$2:$I$33,A34,Findings!$B$2:$B$33,"P2*") | D34: =B34+C34
A35: Fixed | B35: =COUNTIFS(Findings!$I$2:$I$33,A35,Findings!$B$2:$B$33,"P1*") | C35: =COUNTIFS(Findings!$I$2:$I$33,A35,Findings!$B$2:$B$33,"P2*") | D35: =B35+C35
A36: Verified | B36: =COUNTIFS(Findings!$I$2:$I$33,A36,Findings!$B$2:$B$33,"P1*") | C36: =COUNTIFS(Findings!$I$2:$I$33,A36,Findings!$B$2:$B$33,"P2*") | D36: =B36+C36
A37: Won't fix | B37: =COUNTIFS(Findings!$I$2:$I$33,A37,Findings!$B$2:$B$33,"P1*") | C37: =COUNTIFS(Findings!$I$2:$I$33,A37,Findings!$B$2:$B$33,"P2*") | D37: =B37+C37
A38: SRS to update | B38: =COUNTIFS(Findings!$I$2:$I$33,A38,Findings!$B$2:$B$33,"P1*") | C38: =COUNTIFS(Findings!$I$2:$I$33,A38,Findings!$B$2:$B$33,"P2*") | D38: =B38+C38

Sheet Test Cases
A1: TC ID | B1: Suite | C1: Feature | D1: Role | E1: Precondition | F1: Test Steps | G1: Expected Result | H1: Priority | I1: SRS Reference | J1: Requirement IDs | K1: Known Finding | L1: Outlook | M1: 30-min | N1: Status | O1: Actual Result | P1: Defect / Finding ID | Q1: Tester | R1: Date Executed | S1: Build / Commit | T1: Remarks | U1: Verification Method
A2: S-01 | B2: Smoke | C2: Smoke (end-to-end) | D2: See steps | E2: Accounts and dates from §0 of the suite | F2: In a repo checkout run npm run test:roles and then npm run test:booking-time. | G2: Output shows roles test passed: 99 checks and booking time test passed: 8 checks. | H2: P1 | I2: — | J2: REQ-ADM-001, BR-01 | L2: Expected to pass | M2: Y | N2: Pass | O2: roles test passed: 99 checks; booking time test passed: 8 checks | Q2: Claude (automated, no account) | R2: 46302 | S2: Live (Railway main); repo db90eeb | U2: Automated test
A3: S-02 | B3: Smoke | C3: Smoke (end-to-end) | D3: See steps | E3: Accounts and dates from §0 of the suite | F3: Signed out, open /. Click header Catering, then Function Rooms, then Delivery. | G3: Each page renders with no error banner. The header shows Sign In / Log In. | H3: P1 | I3: — | J3: UR-CUST | L3: Expected to pass | M3: N | N3: Not Run
A4: S-03 | B4: Smoke | C4: Smoke (end-to-end) | D4: See steps | E4: Accounts and dates from §0 of the suite | F4: Signed out, go to /operations. | G4: Redirected to / (no staff UI flashes). | H4: P1 | I4: — | J4: REQ-ADM-001 | L4: Expected to pass | M4: Y | N4: Not Run
A5: S-04 | B5: Smoke | C5: Smoke (end-to-end) | D5: See steps | E5: Accounts and dates from §0 of the suite | F5: Signed out, open /delivery/order. Click Buttered Chicken, add Half ×1, click Done · 1 selected, then click Place order · ₱…. | G5: The Sign In modal opens. No order is created. | H5: P1 | I5: — | J5: UR-CUST | L5: Expected to pass | M5: Y | N5: Not Run
A6: S-05 | B6: Smoke | C6: Smoke (end-to-end) | D6: See steps | E6: Accounts and dates from §0 of the suite | F6: In that modal click the Log In tab, enter CUST email and password, and submit. | G6: The modal closes and you are signed in as Juan dela Cruz. The cart is kept and the delivery details modal opens automatically with the name prefilled. If it doesn't, click Place order again and log it as a P2 defect. | H6: P1 | I6: — | J6: UR-CUST | L6: Expected to pass | M6: Y | N6: Not Run
A7: S-06 | B7: Smoke | C7: Smoke (end-to-end) | D7: See steps | E7: Accounts and dates from §0 of the suite | F7: Enter phone 09171234567 and the valid address. Payment: Cash on delivery. Click Place order. | G7: The confirmation screen shows the tracking reference CAP-1xxx. Note it as REF-D. | H7: P1 | I7: — | J7: REQ-DEL-004, SEQ-DEL | L7: Expected to pass | M7: Y | N7: Not Run
A8: S-07 | B8: Smoke | C8: Smoke (end-to-end) | D8: See steps | E8: Accounts and dates from §0 of the suite | F8: Go to /catering/buffet. Select Package A, click Proceed →, pick BUF at 12:00 PM (Guests 10), and confirm. | G8: The success panel shows Booking Reference CAP- followed by 16 characters. Note it as REF-B. | H8: P1 | I8: — | J8: UR-CUST, BR-01, BRIEF | L8: Expected to pass | M8: Y | N8: Not Run
A9: S-08 | B9: Smoke | C9: Smoke (end-to-end) | D9: See steps | E9: Accounts and dates from §0 of the suite | F9: Go to /catering/packed. Add Adobong Manok (defaults to 10 packs), click Proceed, pick BUF at 1:00 PM, and confirm. | G9: Success with a CAP-… reference. The summary shows 10 packs, subtotal ₱1,200, Delivery fee ₱0, total ₱1,200. (Packed meals carry no fee in the app; delivery orders carry ₱60.) | H9: P1 | I9: — | J9: BRIEF | L9: Expected to pass | M9: N | N9: Not Run
A10: S-09 | B10: Smoke | C10: Smoke (end-to-end) | D10: See steps | E10: Accounts and dates from §0 of the suite | F10: Go to /function-rooms/reserve. Fill Name, 09171234567, email, Guests 20, Birthday Celebration. Click Check Availability →, pick FR at 6:00 PM, and confirm. | G10: Success with reference REF-F. Slots before D+2 are disabled. | H10: P1 | I10: — | J10: REQ-RES-001, BR-01, BR-02 | L10: Expected to pass | M10: Y | N10: Not Run
A11: S-10 | B11: Smoke | C11: Smoke (end-to-end) | D11: See steps | E11: Accounts and dates from §0 of the suite | F11: Open /profile. | G11: My bookings lists REF-B, the packed booking and REF-F, all Pending. The delivery tracker with REF-D shows Preparing. | H11: P1 | I11: — | J11: REQ-DEL-004 | L11: Expected to pass | M11: Y | N11: Not Run
A12: S-11 | B12: Smoke | C12: Smoke (end-to-end) | D12: See steps | E12: Accounts and dates from §0 of the suite | F12: Go to /inquiries. Name Juan dela Cruz, email, Type Catering, Message Do you cater on Sundays?. Click Submit. | G12: Success message "Thank you for your inquiry." plus an AI reply (or the fallback text). | H12: P1 | I12: — | J12: REQ-INQ-001, SEQ-INQ | L12: Expected to pass | M12: Y | N12: Not Run
A13: S-12 | B13: Smoke | C13: Smoke (end-to-end) | D13: See steps | E13: Accounts and dates from §0 of the suite | F13: Log out (header → logout → confirm). Log in as FOH. | G13: You land on /operations. Customer nav links are not shown. | H13: P1 | I13: — | J13: REQ-ADM-001 | L13: Expected to pass | M13: Y | N13: Not Run
A14: S-13 | B14: Smoke | C14: Smoke (end-to-end) | D14: See steps | E14: Accounts and dates from §0 of the suite | F14: On /operations, find REF-F under Function room bookings. Open it, set Status Confirmed, click Save changes, then open the Timeline tab. | G14: The row shows Confirmed. The timeline has a new Confirmed entry. Function pending drops by 1. | H14: P1 | I14: — | J14: REQ-ADM-002, SEQ-RES | L14: Expected to pass | M14: Y | N14: Not Run
A15: S-14 | B15: Smoke | C15: Smoke (end-to-end) | D15: See steps | E15: Accounts and dates from §0 of the suite | F15: On /operations, find the S-11 inquiry in the Inquiries panel (wait up to 10 s). | G15: The inquiry is listed (status Resolved because it was auto-answered; see F-07). | H15: P1 | I15: — | J15: REQ-ADM-002 | K15: F-07 | L15: Known deviation | M15: N | N15: Not Run
A16: S-15 | B16: Smoke | C16: Smoke (end-to-end) | D16: See steps | E16: Accounts and dates from §0 of the suite | F16: Go to /delivery/staff. On REF-D set Assign rider = Jun Reyes and Change status = Ready for pickup. | G16: Both changes save instantly. The Jun Reyes rider card shows 1 active delivery. | H16: P1 | I16: — | J16: REQ-DEL-004 | L16: Expected to pass | M16: Y | N16: Not Run
A17: S-16 | B17: Smoke | C17: Smoke (end-to-end) | D17: See steps | E17: Accounts and dates from §0 of the suite | F17: Go to /inquiry-bot. | G17: The page loads with the Needs reply filter active, showing a list or "No Messenger inquiries yet." | H17: P1 | I17: — | J17: REQ-INQ-002 | L17: Expected to pass | M17: N | N17: Not Run
A18: S-17 | B18: Smoke | C18: Smoke (end-to-end) | D18: See steps | E18: Accounts and dates from §0 of the suite | F18: Log out. Log in as RIDER. | G18: You land on /delivery/rider. The header shows Jun Reyes. REF-D appears with the Start delivery button. | H18: P1 | I18: — | J18: UR-RIDER | L18: Expected to pass | M18: Y | N18: Not Run
A19: S-18 | B19: Smoke | C19: Smoke (end-to-end) | D19: See steps | E19: Accounts and dates from §0 of the suite | F19: Click Start delivery, then Mark delivered. Then go to /operations. | G19: Status goes Out for delivery → Delivered. /operations redirects back to /delivery/rider. (The SRS limits riders to setting Delivered; Start delivery is a known deviation → F-25.) | H19: P1 | I19: — | J19: UR-RIDER, REQ-ADM-001 | K19: F-25 | L19: Known deviation | M19: Y | N19: Not Run
A20: S-19 | B20: Smoke | C20: Smoke (end-to-end) | D20: See steps | E20: Accounts and dates from §0 of the suite | F20: Log out. Log in as CUST, open /profile, and search REF-D in the tracker. | G20: The tracker shows Delivered with all four steps complete. | H20: P1 | I20: — | J20: REQ-DEL-004 | L20: Expected to pass | M20: N | N20: Not Run
A21: S-20 | B21: Smoke | C21: Smoke (end-to-end) | D21: See steps | E21: Accounts and dates from §0 of the suite | F21: curl -s -o /dev/null -w '%{http_code}' 'https://capitolrestaurant.up.railway.app/inquiry-bot?hub.mode=subscribe&hub.verify_token=WRONG&hub.challenge=42' | G21: 403 | H21: P1 | I21: — | J21: REQ-INQ-002, CON-01 | L21: Expected to pass | M21: N | N21: Pass | O21: HTTP 403 | Q21: Claude (automated, no account) | R21: 46302 | S21: Live (Railway main); repo db90eeb | U21: Test
A22: AU-01 | B22: Feature | C22: Auth & access | D22: Guest | E22: New email never used | F22: Header → Sign In / Log In → Sign In tab → enter qa.new+1@<domain> → Email me a magic link → open the email → click the link | G22: Back on the site, signed in. A profiles row exists with role = customer and display name = email local-part | H22: P1 | I22: §5.3 Auth, REQ-ADM-001 | J22: REQ-ADM-001, NFR-SEC-02 | L22: Expected to pass | M22: N | N22: Not Run
A23: AU-02 | B23: Feature | C23: Auth & access | D23: CUST | E23: — | F23: Log In tab → correct email + wrong password → submit | G23: Inline error (Invalid login credentials), modal stays open, not signed in | H23: P1 | I23: §5.3 | J23: NFR-SEC-02 | L23: Expected to pass | M23: N | N23: Not Run
A24: AU-03 | B24: Feature | C24: Auth & access | D24: Guest | E24: Google account | F24: Sign In tab → Google button → choose account | G24: Redirected back to the original page, signed in as customer | H24: P2 | I24: §5.3 | J24: NFR-SEC-02 | L24: Expected to pass | M24: N | N24: Not Run
A25: AU-04 | B25: Feature | C25: Auth & access | D25: Guest | E25: — | F25: Log In tab → blank email → submit. Then email juan@ with any password | G25: "Enter your email address", then an inline error from Supabase. Not signed in | H25: P2 | I25: — | J25: BRIEF | L25: Expected to pass | M25: N | N25: Not Run
A26: AU-05 | B26: Feature | C26: Auth & access | D26: FOH | E26: Signed out | F26: Log In as FOH from /catering | G26: Redirected to /operations (role home) | H26: P1 | I26: REQ-ADM-001 | J26: REQ-ADM-001 | L26: Expected to pass | M26: N | N26: Not Run
A27: AU-06 | B27: Feature | C27: Auth & access | D27: RIDER | E27: — | F27: Log In as RIDER from / | G27: Redirected to /delivery/rider | H27: P1 | I27: §2.3 Delivery Rider | J27: UR-RIDER | L27: Expected to pass | M27: N | N27: Not Run
A28: AU-07 | B28: Feature | C28: Auth & access | D28: CUST | E28: Signed in | F28: Header → logout icon → Cancel, then logout → confirm | G28: Cancel keeps the session. Confirm signs out and navigates to /. Visiting /profile then shows "Sign in to view and manage your profile details." | H28: P2 | I28: — | J28: BRIEF | L28: Expected to pass | M28: N | N28: Not Run
A29: AU-08 | B29: Feature | C29: Auth & access | D29: any | E29: Signed in | F29: Hard-refresh (Ctrl+Shift+R) on a guarded page | G29: Loading account... then the same page. No redirect flicker to / | H29: P2 | I29: — | J29: BRIEF | L29: Expected to pass | M29: N | N29: Not Run
A30: AU-09 | B30: Feature | C30: Auth & access | D30: Guest | E30: — | F30: Self-signup: confirm that metadata cannot grant a staff role (covered by supabase/tests/roles_permissions.sql). Manual alternative: sign up via magic link and read the profiles.role value | G30: role = customer | H30: P1 | I30: REQ-ADM-001 | J30: REQ-ADM-001 | L30: Expected to pass | M30: N | N30: Not Run
A31: AU-10 | B31: Feature | C31: Auth & access | D31: Throwaway user with no profiles row | E31: Delete the throwaway user's profiles row (an invalid role can't be set because of the check constraint) | F31: Log in as that user | G31: "Account access unavailable" page, no data shown | H31: P2 | I31: REQ-ADM-001 | J31: REQ-ADM-001 | L31: Expected to pass | M31: N | N31: Not Run
A32: AU-11 | B32: Feature | C32: Auth & access | D32: Guest | E32: New email never used | F32: List every self-service way to create an account (Sign In tab: magic link, Google). For each, check whether the account becomes usable only after the email is proven (link clicked / Google-verified). Then in Supabase → Authentication → Users, confirm the new user has email_confirmed_at set | G32: Every self-signup path verifies the email before a session exists. No path creates a signed-in, unverified account | H32: P1 | I32: §5.3 (customers must verify via email) | J32: NFR-SEC-02 | L32: Expected to pass | M32: N | N32: Not Run
A33: CT-01 | B33: Feature | C33: Catering | D33: Guest | E33: Signed out | F33: /catering/buffet → select Package B → Proceed → | G33: Sign-in modal opens. Calendar does not open | H33: P1 | I33: §2.3 (sign-in required for booking) | J33: UR-CUST | L33: Expected to pass | M33: N | N33: Not Run
... A45: FR-01 | B45: Feature | C45: Function rooms | D45: CUST | E45: — | F45: /function-rooms/reserve → leave every field blank → Check Availability → | G45: Errors on Name, Contact, Email, Guests and Event Type. Calendar does not open | H45: P1 | I45: §5.4 Usability | J45: NFR-USE-01 | L45: Expected to pass | M45: N | N45: Not Run
A46: FR-02 | B46: Feature | C46: Function rooms | D46: CUST | E46: — | F46: Guests 9 with all other fields valid → Check Availability | G46: SRS expects rejection (min 10). The app accepts (min 1) → log F-03 | H46: P1 | I46: BR Party Size | J46: BR-02 | K46: F-03 | L46: Known deviation | M46: Y | N46: Fail | O46: Deployed validation accepts any whole number ≥ 1 ('Enter a whole-number guest count' only below 1), so 9 guests is accepted | P46: F-03 | Q46: Claude (inspection) | R46: 46302 | S46: Live bundle index-Bq1AsZVl.js; source 010694c | T46: Inspection result; re-confirm in the manual run | U46: Inspection
A47: FR-03 | B47: Feature | C47: Function rooms | D47: CUST | E47: — | F47: Guests 31, then 50 | G47: SRS expects 50 to be accepted. The app rejects anything above 30 ("This room holds up to 30 guests") → F-03 | H47: P1 | I47: BR Party Size | J47: BR-02 | K47: F-03 | L47: Known deviation | M47: Y | N47: Fail | O47: Deployed validation rejects > 30 ('This room holds up to 30 guests'), so 31 and 50 are rejected | P47: F-03 | Q47: Claude (inspection) | R47: 46302 | S47: Live bundle index-Bq1AsZVl.js; source 010694c | T47: Inspection result; re-confirm in the manual run | U47: Inspection
A48: FR-04 | B48: Feature | C48: Function rooms | D48: CUST | E48: — | F48: Guests 10, then 30 (boundaries) | G48: Both accepted | H48: P1 | I48: BR Party Size | J48: BR-02 | L48: Expected to pass | M48: N | N48: Pass | O48: 10 and 30 fall inside the deployed 1–30 rule and are accepted | Q48: Claude (inspection) | R48: 46302 | S48: Live bundle index-Bq1AsZVl.js; source 010694c | T48: Inspection result; re-confirm in the manual run | U48: Inspection
A49: FR-05 | B49: Feature | C49: Function rooms | D49: CUST | E49: — | F49: Open Event Type | G49: Options: Birthday Celebration, Debut / 18th Birthday, Wedding Reception, Corporate Event, Family Reunion, Christmas Party, Seminar / Conference, Other | H49: P2 | I49: §5.4 | J49: NFR-USE-01 | L49: Expected to pass | M49: N | N49: Pass | O49: Event types match exactly: Birthday Celebration, Debut / 18th Birthday, Wedding Reception, Corporate Event, Family Reunion, Christmas Party, Seminar / Conference, Other | Q49: Claude (inspection) | R49: 46302 | S49: Live bundle index-Bq1AsZVl.js; source 010694c | T49: Inspection result; re-confirm in the manual run | U49: Inspection
A50: FR-06 | B50: Feature | C50: Function rooms | D50: CUST | E50: — | F50: Contact +639171234567 | G50: Accepted (CONTACT_REGEX allows +639). Compare with DO-05 (delivery rejects it) → F-19 | H50: P2 | I50: — | J50: BRIEF | K50: F-19 | L50: Known deviation | M50: N | N50: Not Run
A51: FR-07 | B51: Feature | C51: Function rooms | D51: CUST | E51: — | F51: Valid form → calendar → try clicking D+1 and then D+2 at 9:00 AM | G51: D+1 is not selectable. D+2 is bookable and succeeds | H51: P1 | I51: BR Lead Time | J51: BR-01 | L51: Expected to pass | M51: N | N51: Not Run
...

Sheet RTM
A1: Req ID | B1: Module | C1: SRS Section | D1: Requirement (summary) | E1: Type | F1: Linked Test Cases | G1: Linked Findings | H1: # Test Cases | I1: Pass | J1: Fail | K1: Blocked | L1: N/A | M1: Not Run | N1: Executed % | O1: Verdict
A2: REQ-INQ-001 | B2: Inquiry Management | C2: §4.1.3 | D2: Signed-in customers submit catering/event inquiries via web form; record created with status New | E2: MUST | F2: S-11, IQ-01, IQ-02, IQ-04 | G2: F-07 | H2: =COUNTIF('Test Cases'!$J$2:$J$155,"*"&A2&"*") | I2: =COUNTIFS('Test Cases'!$J$2:$J$155,"*"&A2&"*",'Test Cases'!$N$2:$N$155,"Pass") | J2: =COUNTIFS('Test Cases'!$J$2:$J$155,"*"&A2&"*",'Test Cases'!$N$2:$N$155,"Fail") | K2: =COUNTIFS('Test Cases'!$J$2:$J$155,"*"&A2&"*",'Test Cases'!$N$2:$N$155,"Blocked") | L2: =COUNTIFS('Test Cases'!$J$2:$J$155,"*"&A2&"*",'Test Cases'!$N$2:$N$155,"N/A") | M2: =COUNTIFS('Test Cases'!$J$2:$J$155,"*"&A2&"*",'Test Cases'!$N$2:$N$155,"Not Run") | N2: =IF(H2=0,0,(H2-M2)/H2) | O2: =IF(H2=0,"No coverage",IF(J2>0,"Fail",IF(M2=H2,"Not run",IF(I2+L2=H2,"Pass","In progress"))))
A3: REQ-INQ-002 | B3: Inquiry Management | C3: §4.1.3 | D3: Capture Facebook Messenger inquiries via Meta Graph API webhook; record within 30 s | E3: MUST | F3: S-16, S-20, IB-01, MA-01, MA-02, MA-04, MA-06 | G3: — | H3: =COUNTIF('Test Cases'!$J$2:$J$155,"*"&A3&"*") | I3: =COUNTIFS('Test Cases'!$J$2:$J$155,"*"&A3&"*",'Test Cases'!$N$2:$N$155,"Pass") | J3: =COUNTIFS('Test Cases'!$J$2:$J$155,"*"&A3&"*",'Test Cases'!$N$2:$N$155,"Fail") | K3: =COUNTIFS('Test Cases'!$J$2:$J$155,"*"&A3&"*",'Test Cases'!$N$2:$N$155,"Blocked") | L3: =COUNTIFS('Test Cases'!$J$2:$J$155,"*"&A3&"*",'Test Cases'!$N$2:$N$155,"N/A") | M3: =COUNTIFS('Test Cases'!$J$2:$J$155,"*"&A3&"*",'Test Cases'!$N$2:$N$155,"Not Run") | N3: =IF(H3=0,0,(H3-M3)/H3) | O3: =IF(H3=0,"No coverage",IF(J3>0,"Fail",IF(M3=H3,"Not run",IF(I3+L3=H3,"Pass","In progress"))))
A4: REQ-INQ-003 | B4: Inquiry Management | C4: §4.1.3 | D4: Show the AI Agent's drafted reply to staff before any reply is sent | E4: MUST | F4: IB-08 | G4: F-10 | H4: =COUNTIF('Test Cases'!$J$2:$J$155,"*"&A4&"*") | I4: =COUNTIFS('Test Cases'!$J$2:$J$155,"*"&A4&"*",'Test Cases'!$N$2:$N$155,"Pass") | J4: =COUNTIFS('Test Cases'!$J$2:$J$155,"*"&A4&"*",'Test Cases'!$N$2:$N$155,"Fail") | K4: =COUNTIFS('Test Cases'!$J$2:$J$155,"*"&A4&"*",'Test Cases'!$N$2:$N$155,"Blocked") | L4: =COUNTIFS('Test Cases'!$J$2:$J$155,"*"&A4&"*",'Test Cases'!$N$2:$N$155,"N/A") | M4: =COUNTIFS('Test Cases'!$J$2:$J$155,"*"&A4&"*",'Test Cases'!$N$2:$N$155,"Not Run") | N4: =IF(H4=0,0,(H4-M4)/H4) | O4: =IF(H4=0,"No coverage",IF(J4>0,"Fail",IF(M4=H4,"Not run",IF(I4+L4=H4,"Pass","In progress"))))
A5: REQ-INQ-004 | B5: Inquiry Management | C5: §4.1.3 | D5: Staff edit and send the AI draft from the dashboard; set status In progress / Resolved | E5: MUST | F5: IQ-06, IB-04, IB-05, IB-06 | G5: — | H5: =COUNTIF('Test Cases'!$J$2:$J$155,"*"&A5&"*") | I5: =COUNTIFS('Test Cases'!$J$2:$J$155,"*"&A5&"*",'Test Cases'!$N$2:$N$155,"Pass") | J5: =COUNTIFS('Test Cases'!$J$2:$J$155,"*"&A5&"*",'Test Cases'!$N$2:$N$155,"Fail") | K5: =COUNTIFS('Test Cases'!$J$2:$J$155,"*"&A5&"*",'Test Cases'!$N$2:$N$155,"Blocked") | L5: =COUNTIFS('Test Cases'!$J$2:$J$155,"*"&A5&"*",'Test Cases'!$N$2:$N$155,"N/A") | M5: =COUNTIFS('Test Cases'!$J$2:$J$155,"*"&A5&"*",'Test Cases'!$N$2:$N$155,"Not Run") | N5: =IF(H5=0,0,(H5-M5)/H5) | O5: =IF(H5=0,"No coverage",IF(J5>0,"Fail",IF(M5=H5,"Not run",IF(I5+L5=H5,"Pass","In progress"))))
A6: SEQ-INQ | B6: Inquiry Management | C6: §4.1.2 | D6: Inquiry flow: received → created as New → acknowledgement ≤ 30 s → staff reply → status update | E6: Flow | F6: S-11, IQ-04, IQ-06, IQ-07, MA-03, MA-06 | G6: F-07 | H6: =COUNTIF('Test Cases'!$J$2:$J$155,"*"&A6&"*") | I6: =COUNTIFS('Test Cases'!$J$2:$J$155,"*"&A6&"*",'Test Cases'!$N$2:$N$155,"Pass") | J6: =COUNTIFS('Test Cases'!$J$2:$J$155,"*"&A6&"*",'Test Cases'!$N$2:$N$155,"Fail") | K6: =COUNTIFS('Test Cases'!$J$2:$J$155,"*"&A6&"*",'Test Cases'!$N$2:$N$155,"Blocked") | L6: =COUNTIFS('Test Cases'!$J$2:$J$155,"*"&A6&"*",'Test Cases'!$N$2:$N$155,"N/A") | M6: =COUNTIFS('Test Cases'!$J$2:$J$155,"*"&A6&"*",'Test Cases'!$N$2:$N$155,"Not Run") | N6: =IF(H6=0,0,(H6-M6)/H6) | O6: =IF(H6=0,"No coverage",IF(J6>0,"Fail",IF(M6=H6,"Not run",IF(I6+L6=H6,"Pass","In progress"))))
A7: REQ-RES-001 | B7: Reservation | C7: §4.2.3 | D7: Real-time calendar showing availability, blocked dates and open slots | E7: MUST | F7: S-09, FR-08, FR-09, FR-11, OP-07, DB-03, DB-11 | G7: — | H7: =COUNTIF('Test Cases'!$J$2:$J$155,"*"&A7&"*") | I7: =COUNTIFS('Test Cases'!$J$2:$J$155,"*"&A7&"*",'Test Cases'!$N$2:$N$155,"Pass") | J7: =COUNTIFS('Test Cases'!$J$2:$J$155,"*"&A7&"*",'Test Cases'!$N$2:$N$155,"Fail") | K7: =COUNTIFS('Test Cases'!$J$2:$J$155,"*"&A7&"*",'Test Cases'!$N$2:$N$155,"Blocked") | L7: =COUNTIFS('Test Cases'!$J$2:$J$155,"*"&A7&"*",'Test Cases'!$N$2:$N$155,"N/A") | M7: =COUNTIFS('Test Cases'!$J$2:$J$155,"*"&A7&"*",'Test Cases'!$N$2:$N$155,"Not Run") | N7: =IF(H7=0,0,(H7-M7)/H7) | O7: =IF(H7=0,"No coverage",IF(J7>0,"Fail",IF(M7=H7,"Not run",IF(I7+L7=H7,"Pass","In progress"))))
A8: REQ-RES-002 | B8: Reservation | C8: §4.2.3 | D8: Database-level locking prevents simultaneous double-booking | E8: MUST | F8: CT-09, FR-08, OP-03, OP-04, DB-08, DB-09 | G8: F-31 | H8: =COUNTIF('Test Cases'!$J$2:$J$155,"*"&A8&"*") | I8: =COUNTIFS('Test Cases'!$J$2:$J$155,"*"&A8&"*",'Test Cases'!$N$2:$N$155,"Pass") | J8: =COUNTIFS('Test Cases'!$J$2:$J$155,"*"&A8&"*",'Test Cases'!$N$2:$N$155,"Fail") | K8: =COUNTIFS('Test Cases'!$J$2:$J$155,"*"&A8&"*",'Test Cases'!$N$2:$N$155,"Blocked") | L8: =COUNTIFS('Test Cases'!$J$2:$J$155,"*"&A8&"*",'Test Cases'!$N$2:$N$155,"N/A") | M8: =COUNTIFS('Test Cases'!$J$2:$J$155,"*"&A8&"*",'Test Cases'!$N$2:$N$155,"Not Run") | N8: =IF(H8=0,0,(H8-M8)/H8) | O8: =IF(H8=0,"No coverage",IF(J8>0,"Fail",IF(M8=H8,"Not run",IF(I8+L8=H8,"Pass","In progress"))))
A9: REQ-RES-003 | B9: Reservation | C9: §4.2.3 | D9: Minimum deposit via payment gateway before a reservation is locked | E9: MUST | F9: FR-10, DB-06 | G9: F-04, F-12 | H9: =COUNTIF('Test Cases'!$J$2:$J$155,"*"&A9&"*") | I9: =COUNTIFS('Test Cases'!$J$2:$J$155,"*"&A9&"*",'Test Cases'!$N$2:$N$155,"Pass") | J9: =COUNTIFS('Test Cases'!$J$2:$J$155,"*"&A9&"*",'Test Cases'!$N$2:$N$155,"Fail") | K9: =COUNTIFS('Test Cases'!$J$2:$J$155,"*"&A9&"*",'Test Cases'!$N$2:$N$155,"Blocked") | L9: =COUNTIFS('Test Cases'!$J$2:$J$155,"*"&A9&"*",'Test Cases'!$N$2:$N$155,"N/A") | M9: =COUNTIFS('Test Cases'!$J$2:$J$155,"*"&A9&"*",'Test Cases'!$N$2:$N$155,"Not Run") | N9: =IF(H9=0,0,(H9-M9)/H9) | O9: =IF(H9=0,"No coverage",IF(J9>0,"Fail",IF(M9=H9,"Not run",IF(I9+L9=H9,"Pass","In progress"))))
A10: REQ-RES-004 | B10: Reservation | C10: §4.2.3 | D10: Managers can block out dates/times (maintenance, private events) | E10: MUST | F10: FR-13 | G10: F-14 | H10: =COUNTIF('Test Cases'!$J$2:$J$155,"*"&A10&"*") | I10: =COUNTIFS('Test Cases'!$J$2:$J$155,"*"&A10&"*",'Test Cases'!$N$2:$N$155,"Pass") | J10: =COUNTIFS('Test Cases'!$J$2:$J$155,"*"&A10&"*",'Test Cases'!$N$2:$N$155,"Fail") | K10: =COUNTIFS('Test Cases'!$J$2:$J$155,"*"&A10&"*",'Test Cases'!$N$2:$N$155,"Blocked") | L10: =COUNTIFS('Test Cases'!$J$2:$J$155,"*"&A10&"*",'Test Cases'!$N$2:$N$155,"N/A") | M10: =COUNTIFS('Test Cases'!$J$2:$J$155,"*"&A10&"*",'Test Cases'!$N$2:$N$155,"Not Run") | N10: =IF(H10=0,0,(H10-M10)/H10) | O10: =IF(H10=0,"No coverage",IF(J10>0,"Fail",IF(M10=H10,"Not run",IF(I10+L10=H10,"Pass","In progress"))))
A11: REQ-RES-005 | B11: Reservation | C11: §4.2.3 | D11: Release a locked slot if the deposit is not paid within 10 minutes | E11: MUST | F11: FR-10 | G11: F-05 | H11: =COUNTIF('Test Cases'!$J$2:$J$155,"*"&A11&"*") | I11: =COUNTIFS('Test Cases'!$J$2:$J$155,"*"&A11&"*",'Test Cases'!$N$2:$N$155,"Pass") | J11: =COUNTIFS('Test Cases'!$J$2:$J$155,"*"&A11&"*",'Test Cases'!$N$2:$N$155,"Fail") | K11: =COUNTIFS('Test Cases'!$J$2:$J$155,"*"&A11&"*",'Test Cases'!$N$2:$N$155,"Blocked") | L11: =COUNTIFS('Test Cases'!$J$2:$J$155,"*"&A11&"*",'Test Cases'!$N$2:$N$155,"N/A") | M11: =COUNTIFS('Test Cases'!$J$2:$J$155,"*"&A11&"*",'Test Cases'!$N$2:$N$155,"Not Run") | N11: =IF(H11=0,0,(H11-M11)/H11) | O11: =IF(H11=0,"No coverage",IF(J11>0,"Fail",IF(M11=H11,"Not run",IF(I11+L11=H11,"Pass","In progress"))))
A12: SEQ-RES | B12: Reservation | C12: §4.2.2 | D12: Booking flow: select room/date/time/duration → atomic check → 10-min lock → Pending Deposit → Confirmed; 'Already Reserved' on conflict | E12: Flow | F12: S-13, CT-09, FR-08, FR-11, FR-15, OP-02 | G12: F-28 | H12: =COUNTIF('Test Cases'!$J$2:$J$155,"*"&A12&"*") | I12: =COUNTIFS('Test Cases'!$J$2:$J$155,"*"&A12&"*",'Test Cases'!$N$2:$N$155,"Pass") | J12: =COUNTIFS('Test Cases'!$J$2:$J$155,"*"&A12&"*",'Test Cases'!$N$2:$N$155,"Fail") | K12: =COUNTIFS('Test Cases'!$J$2:$J$155,"*"&A12&"*",'Test Cases'!$N$2:$N$155,"Blocked") | L12: =COUNTIFS('Test Cases'!$J$2:$J$155,"*"&A12&"*",'Test Cases'!$N$2:$N$155,"N/A") | M12: =COUNTIFS('Test Cases'!$J$2:$J$155,"*"&A12&"*",'Test Cases'!$N$2:$N$155,"Not Run") | N12: =IF(H12=0,0,(H12-M12)/H12) | O12: =IF(H12=0,"No coverage",IF(J12>0,"Fail",IF(M12=H12,"Not run",IF(I12+L12=H12,"Pass","In progress"))))
A13: REQ-DEL-001 | B13: Food Delivery | C13: §4.3.3 | D13: Categorised menu with photos, descriptions, pricing and allergen/dietary tags | E13: MUST | F13: DO-01, DO-03, DO-13 | G13: F-23 | H13: =COUNTIF('Test Cases'!$J$2:$J$155,"*"&A13&"*") | I13: =COUNTIFS('Test Cases'!$J$2:$J$155,"*"&A13&"*",'Test Cases'!$N$2:$N$155,"Pass") | J13: =COUNTIFS('Test Cases'!$J$2:$J$155,"*"&A13&"*",'Test Cases'!$N$2:$N$155,"Fail") | K13: =COUNTIFS('Test Cases'!$J$2:$J$155,"*"&A13&"*",'Test Cases'!$N$2:$N$155,"Blocked") | L13: =COUNTIFS('Test Cases'!$J$2:$J$155,"*"&A13&"*",'Test Cases'!$N$2:$N$155,"N/A") | M13: =COUNTIFS('Test Cases'!$J$2:$J$155,"*"&A13&"*",'Test Cases'!$N$2:$N$155,"Not Run") | N13: =IF(H13=0,0,(H13-M13)/H13) | O13: =IF(H13=0,"No coverage",IF(J13>0,"Fail",IF(M13=H13,"Not run",IF(I13+L13=H13,"Pass","In progress"))))
... A41: BRIEF | B41: Not in SRS | C41: — | D41: Behaviour from the test brief or the app itself (no SRS requirement); traced for completeness | E41: — | F41: S-07, S-08, AU-04, AU-07, AU-08, CT-02, CT-04, CT-05, CT-06, CT-07, CT-08, CT-10, CT-12, FR-06, DO-05, DO-07, DO-12, DS-03, DS-04, DS-10, DS-11, DS-12, IQ-03, IQ-08, IB-02, IB-03, IB-07, MA-05, MA-07, MA-08, MA-09, PR-02, PR-05, OP-05, OP-06, DB-09 | G41: F-11, F-19 | H41: =COUNTIF('Test Cases'!$J$2:$J$155,"*"&A41&"*") | I41: =COUNTIFS('Test Cases'!$J$2:$J$155,"*"&A41&"*",'Test Cases'!$N$2:$N$155,"Pass") | J41: =COUNTIFS('Test Cases'!$J$2:$J$155,"*"&A41&"*",'Test Cases'!$N$2:$N$155,"Fail") | K41: =COUNTIFS('Test Cases'!$J$2:$J$155,"*"&A41&"*",'Test Cases'!$N$2:$N$155,"Blocked") | L41: =COUNTIFS('Test Cases'!$J$2:$J$155,"*"&A41&"*",'Test Cases'!$N$2:$N$155,"N/A") | M41: =COUNTIFS('Test Cases'!$J$2:$J$155,"*"&A41&"*",'Test Cases'!$N$2:$N$155,"Not Run") | N41: =IF(H41=0,0,(H41-M41)/H41) | O41: =IF(H41=0,"No coverage",IF(J41>0,"Fail",IF(M41=H41,"Not run",IF(I41+L41=H41,"Pass","In progress"))))
A43: Counts and verdicts are formulas over Test Cases → Requirement IDs (col J) and Status (col N). IDs other than REQ-* are assigned by this RTM because the SRS does not number those items; see Cover.

Sheet Findings
A1: Finding ID | B1: Severity | C1: Finding | D1: Evidence (code @ 010694c) | E1: SRS Reference | F1: Requirement IDs | G1: Linked Test Cases | H1: Failed Cases | I1: Status | J1: Owner | K1: Target Date | L1: Resolution Notes
A2: F-01 | B2: P1 | C2: Web delivery orders are stored only in the browser's localStorage, not in Supabase delivery_orders. Staff, riders and customers on other devices never see them | D2: src/data/delivery.ts:200-216, DeliveryOrder.tsx:252-280; no delivery_orders query anywhere in src/ | E2: REQ-DEL-004, REQ-ADM-002 | F2: REQ-DEL-004, REQ-ADM-002 | G2: DO-08, DS-14 | H2: =COUNTIFS('Test Cases'!$P$2:$P$155,"*"&A2&"*",'Test Cases'!$N$2:$N$155,"Fail") | I2: Open | L2: Confirmed by inspection of the deployed build on 2026-10-07; still open (not fixed)
A3: F-02 | B3: P1 | C3: The order reference is CAP-${1050 + local order count}, generated client-side, so duplicates across devices are possible. The DB function next_delivery_reference() is unused | D3: DeliveryOrder.tsx:253 | E3: REQ-DEL-004 | F3: REQ-DEL-004 | G3: DO-09 | H3: =COUNTIFS('Test Cases'!$P$2:$P$155,"*"&A3&"*",'Test Cases'!$N$2:$N$155,"Fail") | I3: Open | L3: Confirmed by inspection of the deployed build on 2026-10-07; still open (not fixed)
A4: F-03 | B4: P1 | C4: Function room accepts 1–30 guests. The SRS says 10–50 | D4: FunctionRoomReservation.tsx:76-80, maxPax={30} | E4: BR Party Size | F4: BR-02 | G4: FR-02, FR-03 | H4: =COUNTIFS('Test Cases'!$P$2:$P$155,"*"&A4&"*",'Test Cases'!$N$2:$N$155,"Fail") | I4: Open | L4: Confirmed by inspection of the deployed build on 2026-10-07; still open (not fixed)
A5: F-04 | B5: P1 | C5: No payment gateway or deposit: bookings are created as Pending with no payment, and the GCash/Card options are labels only. PayMaya (REQ-DEL-003) is not offered | D5: reservations.ts:155, DeliveryOrder.tsx:893 | E5: REQ-RES-003, REQ-DEL-003 | F5: REQ-RES-003, REQ-DEL-003 | G5: FR-10, DO-10 | H5: =COUNTIFS('Test Cases'!$P$2:$P$155,"*"&A5&"*",'Test Cases'!$N$2:$N$155,"Fail") | I5: Open | L5: Confirmed by inspection of the deployed build on 2026-10-07; still open (not fixed)
A6: F-05 | B6: P1 | C6: No 10-minute slot hold or expiry. The slot is occupied as soon as the booking is Pending and stays occupied until staff cancel it | D6: No hold logic in the migrations or src/ | E6: REQ-RES-005 | F6: REQ-RES-005 | G6: FR-10 | H6: =COUNTIFS('Test Cases'!$P$2:$P$155,"*"&A6&"*",'Test Cases'!$N$2:$N$155,"Fail") | I6: Open | L6: Confirmed by inspection of the deployed build on 2026-10-07; still open (not fixed)
A7: F-06 | B7: P1 | C7: No confirmation email or self-cancel link | D7: No SMTP/Resend code | E7: BR Cancellation, §3.3 | F7: BR-04, IF-SW-01 | G7: FR-12 | H7: =COUNTIFS('Test Cases'!$P$2:$P$155,"*"&A7&"*",'Test Cases'!$N$2:$N$155,"Fail") | I7: Open | L7: Confirmed by inspection of the deployed build on 2026-10-07; still open (not fixed)
A8: F-07 | B8: P1 | C8: The web inquiry form does not require sign-in, the server always saves user_id = null (even for a signed-in customer, so the inquiry is never linked to the account), and non-order inquiries are saved as Resolved instead of New | D8: Inquiries.tsx, webhook.js:820-828 | E8: REQ-INQ-001, §4.1.2-2 | F8: REQ-INQ-001, SEQ-INQ | G8: IQ-01, IQ-07, S-14 | H8: =COUNTIFS('Test Cases'!$P$2:$P$155,"*"&A8&"*",'Test Cases'!$N$2:$N$155,"Fail") | I8: Open | L8: Confirmed by inspection of the deployed build on 2026-10-07; still open (not fixed)
A9: F-08 | B9: P1 | C9: Front-of-house can edit the menu (/delivery/items), and catalog RLS gives FOH write access to packages, items, rooms and blackout dates | D9: roles.ts OPERATIONS_PATHS; migration 20260917082142 operational_predicate | E9: BR Menu & Pricing Authority | F9: BR-03 | G9: DS-08, S-08 | H9: =COUNTIFS('Test Cases'!$P$2:$P$155,"*"&A9&"*",'Test Cases'!$N$2:$N$155,"Fail") | I9: Open | L9: Confirmed by inspection of the deployed build on 2026-10-07; still open (not fixed)
A10: F-09 | B10: P1 | C10: Menu manager edits (items, categories, visibility) are stored in localStorage only, so they are not persisted to the DB or shown to other customers | D10: src/data/deliveryMenu.ts | E10: REQ-ADM-003, §4.4.2-4 | F10: REQ-ADM-003, SEQ-ADM | G10: DS-06, S-06 | H10: =COUNTIFS('Test Cases'!$P$2:$P$155,"*"&A10&"*",'Test Cases'!$N$2:$N$155,"Fail") | I10: Open | L10: Confirmed by inspection of the deployed build on 2026-10-07; still open (not fixed)
A11: F-10 | B11: P1 | C11: The Inquiry Bot page shows no AI-drafted reply for staff to edit | D11: InquiryBot.tsx (no draft field) | E11: REQ-INQ-003 | F11: REQ-INQ-003 | G11: IB-08 | H11: =COUNTIFS('Test Cases'!$P$2:$P$155,"*"&A11&"*",'Test Cases'!$N$2:$N$155,"Fail") | I11: Open | L11: Confirmed by inspection of the deployed build on 2026-10-07; still open (not fixed)
A12: F-11 | B12: P1 (brief) | C12: The Messenger agent never creates orders (place_order → "we can't take orders here"), so no source = messenger rows are written, although the schema supports them | D12: webhook.js:525, :950-953 | E12: — (the test brief expects it; the SRS does not require it) | F12: BRIEF | G12: MA-07 | H12: =COUNTIFS('Test Cases'!$P$2:$P$155,"*"&A12&"*",'Test Cases'!$N$2:$N$155,"Fail") | I12: Open | L12: Confirmed by inspection of the deployed build on 2026-10-07; still open (not fixed)
A13: F-12 | B13: P1 | C13: Customer RLS allows updating any column of their own booking or order, including status (e.g., self-Confirmed) | D13: Migration 20260917082142 update policy | E13: REQ-RES-003, §5.3 | F13: REQ-RES-003, NFR-SEC-02 | G13: DB-06 | H13: =COUNTIFS('Test Cases'!$P$2:$P$155,"*"&A13&"*",'Test Cases'!$N$2:$N$155,"Fail") | I13: Open
A14: F-13 | B14: P1 | C14: A rider account whose display name doesn't match a rider record sees the first rider's orders | D14: DeliveryRider.tsx:26-34 | E14: §2.3 Rider ("assigned orders") | F14: UR-RIDER | G14: DS-11, S-11 | H14: =COUNTIFS('Test Cases'!$P$2:$P$155,"*"&A14&"*",'Test Cases'!$N$2:$N$155,"Fail") | I14: Open | L14: Confirmed by inspection of the deployed build on 2026-10-07; still open (not fixed)
A15: F-14 | B15: P2 | C15: There is no UI for managers to block out dates; reserved_dates can only be edited in the DB | D15: No write to reserved_dates in src/ | E15: REQ-RES-004 | F15: REQ-RES-004 | G15: FR-13 | H15: =COUNTIFS('Test Cases'!$P$2:$P$155,"*"&A15&"*",'Test Cases'!$N$2:$N$155,"Fail") | I15: Open | L15: Confirmed by inspection of the deployed build on 2026-10-07; still open (not fixed)
A16: F-15 | B16: P2 | C16: The booking form has no data-privacy consent checkbox | D16: No "consent" in src/ | E16: §5.3 Data Privacy | F16: NFR-SEC-01 | G16: FR-14 | H16: =COUNTIFS('Test Cases'!$P$2:$P$155,"*"&A16&"*",'Test Cases'!$N$2:$N$155,"Fail") | I16: Open | L16: Confirmed by inspection of the deployed build on 2026-10-07; still open (not fixed)
A17: F-16 | B17: P1 | C17: The 2-day lead time is enforced only in the client. The DB accepts same-day bookings | D17: CalendarModal.tsx:201-209; no DB check | E17: BR Lead Time | F17: BR-01 | G17: DB-10 | H17: =COUNTIFS('Test Cases'!$P$2:$P$155,"*"&A17&"*",'Test Cases'!$N$2:$N$155,"Fail") | I17: Open
A18: F-17 | B18: P2 | C18: system_admin can open Operations but RLS denies writes, so status changes fail or silently revert | D18: Migration 20260917082142 (operational_predicate excludes system_admin) | E18: §2.3 (Administrator: full access), REQ-ADM-001 | F18: REQ-ADM-001, UR-ADMIN | G18: DB-14 | H18: =COUNTIFS('Test Cases'!$P$2:$P$155,"*"&A18&"*",'Test Cases'!$N$2:$N$155,"Fail") | I18: Open
A19: F-18 | B19: P1 | C19: POST /inquiry-bot has no Meta signature check, and VERIFY_TOKEN falls back to test-agent when the env var is unset | D19: webhook.js:75, :975. Confirmed live 2026-10-07: unsigned POST returns 200, and the verify token test-agent is accepted, so VERIFY_TOKEN is not set on Railway | E19: §5.3, §2.5 Vendor | F19: NFR-SEC-02, CON-01 | G19: DB-15, MA-01 | H19: =COUNTIFS('Test Cases'!$P$2:$P$155,"*"&A19&"*",'Test Cases'!$N$2:$N$155,"Fail") | I19: Open | L19: Confirmed on the live site 2026-10-07 (DB-15 fail; MA-01 accepted the fallback token). Fix: set VERIFY_TOKEN and APP_SECRET on Railway and verify X-Hub-Signature-256
A20: F-19 | B20: P2 | C20: Phone rules differ between forms: function room and catering accept +639…, delivery and profile accept only 09… | D20: FunctionRoomReservation.tsx:16 vs DeliveryOrder.tsx:46 | E20: — (internal consistency) | F20: BRIEF | G20: FR-06, DO-05 | H20: =COUNTIFS('Test Cases'!$P$2:$P$155,"*"&A20&"*",'Test Cases'!$N$2:$N$155,"Fail") | I20: Open
A21: F-20 | B21: P2 | C21: The delivery status flow differs: the SRS has Received → Preparing → Out for Delivery → Delivered; the app has Preparing → Ready for pickup → Out for delivery → Delivered | D21: delivery.ts:49 | E21: §4.3.2-5 | F21: SEQ-DEL | G21: DS-02, S-02 | H21: =COUNTIFS('Test Cases'!$P$2:$P$155,"*"&A21&"*",'Test Cases'!$N$2:$N$155,"Fail") | I21: Open
A22: F-21 | B22: P2 | C22: Packed-meal bookings are saved with email = "", so staff cannot email the customer | D22: CateringPacked.tsx:292 | E22: §3.3 SMTP | F22: IF-SW-01 | G22: CT-12 | H22: =COUNTIFS('Test Cases'!$P$2:$P$155,"*"&A22&"*",'Test Cases'!$N$2:$N$155,"Fail") | I22: Open
A23: F-22 | B23: P1 | C23: No reporting module: /dashboard shows charts but has no sales-value or room-utilisation summary and no export | D23: Dashboard.tsx (no CSV/PDF/download code) | E23: REQ-ADM-004 | F23: REQ-ADM-004 | G23: OP-09 | H23: =COUNTIFS('Test Cases'!$P$2:$P$155,"*"&A23&"*",'Test Cases'!$N$2:$N$155,"Fail") | I23: Open | L23: Confirmed by inspection of the deployed build on 2026-10-07; still open (not fixed)
A24: F-23 | B24: P2 | C24: Menu items have no allergen or dietary tags | D24: No "allergen" anywhere in src/ | E24: REQ-DEL-001 | F24: REQ-DEL-001 | G24: DO-13 | H24: =COUNTIFS('Test Cases'!$P$2:$P$155,"*"&A24&"*",'Test Cases'!$N$2:$N$155,"Fail") | I24: Open | L24: Confirmed by inspection of the deployed build on 2026-10-07; still open (not fixed)
A25: F-24 | B25: P2 | C25: Customisation notes are per order, not per item | D25: DeliveryOrder.tsx:900 (single Notes field) | E25: REQ-DEL-002 | F25: REQ-DEL-002 | G25: DO-14 | H25: =COUNTIFS('Test Cases'!$P$2:$P$155,"*"&A25&"*",'Test Cases'!$N$2:$N$155,"Fail") | I25: Open | L25: Confirmed by inspection of the deployed build on 2026-10-07; still open (not fixed)
A26: F-25 | B26: P2 | C26: Riders can set Out for delivery as well as Delivered | D26: DeliveryRider.tsx:36-44 (NEXT_STATUS) | E26: §2.3 Delivery Rider | F26: UR-RIDER | G26: DS-13, S-13, S-18 | H26: =COUNTIFS('Test Cases'!$P$2:$P$155,"*"&A26&"*",'Test Cases'!$N$2:$N$155,"Fail") | I26: Open | L26: Confirmed by inspection of the deployed build on 2026-10-07; still open (not fixed)
A27: F-26 | B27: P2 | C27: No audible chime and no live refresh for new delivery orders on the staff page | D27: No audio code in src/; AdminDelivery.tsx has no polling or storage listener | E27: §4.3.2-4, §3.1 | F27: IF-UI-01, SEQ-DEL | G27: DS-14, S-14 | H27: =COUNTIFS('Test Cases'!$P$2:$P$155,"*"&A27&"*",'Test Cases'!$N$2:$N$155,"Fail") | I27: Open | L27: Confirmed by inspection of the deployed build on 2026-10-07; still open (not fixed)
A28: F-27 | B28: P2 | C28: Inquiries and dashboard counts arrive by 10-second polling, not WebSocket/SSE push (bookings do use Supabase Realtime) | D28: setInterval in Operations.tsx, InquiryBot.tsx, Dashboard.tsx | E28: §3.4, §3.1 | F28: IF-UI-01, IF-COM-01 | G28: IQ-05 | H28: =COUNTIFS('Test Cases'!$P$2:$P$155,"*"&A28&"*",'Test Cases'!$N$2:$N$155,"Fail") | I28: Open
A29: F-28 | B29: P2 | C29: Booking flow differs from §4.2.2: no duration choice, status Pending instead of Pending Deposit, collision text differs from "Already Reserved" | D29: reservations.ts:7; CalendarModal.tsx | E29: §4.2.2-1, -4, -5 | F29: SEQ-RES | G29: FR-15 | H29: =COUNTIFS('Test Cases'!$P$2:$P$155,"*"&A29&"*",'Test Cases'!$N$2:$N$155,"Fail") | I29: Open | L29: Confirmed by inspection of the deployed build on 2026-10-07; still open (not fixed)
A30: F-29 | B30: P2 | C30: Staff cannot flag late cancellations or no-shows | D30: ReservationStatus has no such value (reservations.ts:7) | E30: BR Cancellation | F30: BR-04 | G30: FR-16 | H30: =COUNTIFS('Test Cases'!$P$2:$P$155,"*"&A30&"*",'Test Cases'!$N$2:$N$155,"Fail") | I30: Open | L30: Confirmed by inspection of the deployed build on 2026-10-07; still open (not fixed)
A31: F-30 | B31: P2 | C31: Operations stat cards differ from the SRS widgets: no Room Occupancy, and revenue appears only as a hint | D31: Operations.tsx:277-281 | E31: §4.4.2-3 | F31: SEQ-ADM | G31: OP-08 | H31: =COUNTIFS('Test Cases'!$P$2:$P$155,"*"&A31&"*",'Test Cases'!$N$2:$N$155,"Fail") | I31: Open | L31: Confirmed by inspection of the deployed build on 2026-10-07; still open (not fixed)
A32: F-31 | B32: P2 (docs) | C32: The SRS architecture doesn't match the build: Python FastAPI backend vs. Express webhook.js; SELECT FOR UPDATE vs. a partial unique index for slot locking. Behaviour is equivalent; update the SRS (§2.1, §2.4, REQ-RES-002) or record a design decision | D32: webhook.js; migration unique index function_bookings_active_slot_unique | E32: §2.1, §2.4, REQ-RES-002 | F32: REQ-RES-002, ARCH-01 | G32: DB-08 | H32: =COUNTIFS('Test Cases'!$P$2:$P$155,"*"&A32&"*",'Test Cases'!$N$2:$N$155,"Fail") | I32: SRS to update | L32: QA recommendation: behaviour is equivalent, so update SRS §2.1, §2.4 and REQ-RES-002 rather than the code. Confirm with the team
A33: F-32 | B33: P2 | C33: The Supabase catalog tables (catering_packages, packed_menu_items, function_rooms) are never read by the app, and their data disagrees with what customers see: the DB has Package 1–3 for 50–500 guests, the site shows Package A–C for 10–12 guests from serviceCatalog.json. Catalog edits in the DB never reach the site, so the catalog write access in F-08 has no UI effect and REQ-ADM-003 cannot be met through the DB | D33: No query on those tables in src/ or webhook.js; seed in migration 20260827090541:139-141; live anon GET on 2026-10-07 | E33: REQ-ADM-003, §4.4.2-4 | F33: REQ-ADM-003, SEQ-ADM | G33: DS-06, S-06 | H33: =COUNTIFS('Test Cases'!$P$2:$P$155,"*"&A33&"*",'Test Cases'!$N$2:$N$155,"Fail") | I33: Open | L33: Found on the live site 2026-10-07 (anon GET catering_packages returned Package 1–3, 50–500 pax)
A35: Failed Cases counts test cases whose Defect / Finding ID contains this finding and whose Status is Fail. Note: 'F-1' style partial matches are avoided because IDs are two digits (F-01 … F-31).
